Workbook

Sheet Matches
A1: Match No | B1: Date | C1: Stage | D1: Team_A | E1: Team_B | F1: Goals_A | G1: Goals_B | H1: Shootout | I1: Goal_diff | J1: Knockout
A2: 1 | B2: 46184 | C2: Group stage | D2: Mexico | E2: South Africa | F2: 2 | G2: 0 | I2: =IF(OR(F2="",G2=""),"",F2-G2) -> 2 | J2: =IF(TRIM(C2)="Group stage",0,1) -> 0
A3: 2 | B3: 46184 | C3: Group stage | D3: Korea Republic | E3: Czechia | F3: 2 | G3: 1 | I3: =IF(OR(F3="",G3=""),"",F3-G3) -> 1 | J3: =IF(TRIM(C3)="Group stage",0,1) -> 0
A4: 3 | B4: 46185 | C4: Group stage | D4: Canada | E4: Bosnia and Herzegovina | F4: 1 | G4: 1 | I4: =IF(OR(F4="",G4=""),"",F4-G4) -> 0 | J4: =IF(TRIM(C4)="Group stage",0,1) -> 0
A5: 4 | B5: 46185 | C5: Group stage | D5: USA | E5: Paraguay | F5: 4 | G5: 1 | I5: =IF(OR(F5="",G5=""),"",F5-G5) -> 3 | J5: =IF(TRIM(C5)="Group stage",0,1) -> 0
A6: 5 | B6: 46186 | C6: Group stage | D6: Qatar | E6: Switzerland | F6: 1 | G6: 1 | I6: =IF(OR(F6="",G6=""),"",F6-G6) -> 0 | J6: =IF(TRIM(C6)="Group stage",0,1) -> 0
A7: 6 | B7: 46186 | C7: Group stage | D7: Brazil | E7: Morocco | F7: 1 | G7: 1 | I7: =IF(OR(F7="",G7=""),"",F7-G7) -> 0 | J7: =IF(TRIM(C7)="Group stage",0,1) -> 0
A8: 7 | B8: 46186 | C8: Group stage | D8: Australia | E8: Türkiye | F8: 2 | G8: 0 | I8: =IF(OR(F8="",G8=""),"",F8-G8) -> 2 | J8: =IF(TRIM(C8)="Group stage",0,1) -> 0
A9: 8 | B9: 46186 | C9: Group stage | D9: Haiti | E9: Scotland | F9: 0 | G9: 1 | I9: =IF(OR(F9="",G9=""),"",F9-G9) -> -1 | J9: =IF(TRIM(C9)="Group stage",0,1) -> 0
A10: 9 | B10: 46187 | C10: Group stage | D10: Germany | E10: Curaçao | F10: 7 | G10: 1 | I10: =IF(OR(F10="",G10=""),"",F10-G10) -> 6 | J10: =IF(TRIM(C10)="Group stage",0,1) -> 0
A11: 10 | B11: 46187 | C11: Group stage | D11: Netherlands | E11: Japan | F11: 2 | G11: 2 | I11: =IF(OR(F11="",G11=""),"",F11-G11) -> 0 | J11: =IF(TRIM(C11)="Group stage",0,1) -> 0
A12: 11 | B12: 46187 | C12: Group stage | D12: Côte d'Ivoire | E12: Ecuador | F12: 1 | G12: 0 | I12: =IF(OR(F12="",G12=""),"",F12-G12) -> 1 | J12: =IF(TRIM(C12)="Group stage",0,1) -> 0
A13: 12 | B13: 46187 | C13: Group stage | D13: Sweden | E13: Tunisia | F13: 5 | G13: 1 | I13: =IF(OR(F13="",G13=""),"",F13-G13) -> 4 | J13: =IF(TRIM(C13)="Group stage",0,1) -> 0
... A75: 74 | B75: 46202 | C75: Round of 32 | D75: Brazil | E75: Japan | F75: 2 | G75: 1 | I75: =IF(OR(F75="",G75=""),"",F75-G75) -> 1 | J75: =IF(TRIM(C75)="Group stage",0,1) -> 1
A76: 75 | B76: 46202 | C76: Round of 32 | D76: Germany | E76: Paraguay | F76: 1 | G76: 1 | H76: 3-4 | I76: =IF(OR(F76="",G76=""),"",F76-G76) -> 0 | J76: =IF(TRIM(C76)="Group stage",0,1) -> 1
A77: 76 | B77: 46202 | C77: Round of 32 | D77: Netherlands | E77: Morocco | F77: 1 | G77: 1 | H77: 2-3 | I77: =IF(OR(F77="",G77=""),"",F77-G77) -> 0 | J77: =IF(TRIM(C77)="Group stage",0,1) -> 1
A78: 77 | B78: 46203 | C78: Round of 32 | D78: Côte d'Ivoire | E78: Norway | F78: 1 | G78: 2 | I78: =IF(OR(F78="",G78=""),"",F78-G78) -> -1 | J78: =IF(TRIM(C78)="Group stage",0,1) -> 1
A79: 78 | B79: 46203 | C79: Round of 32 | D79: France | E79: Sweden | F79: 3 | G79: 0 | I79: =IF(OR(F79="",G79=""),"",F79-G79) -> 3 | J79: =IF(TRIM(C79)="Group stage",0,1) -> 1
A80: 79 | B80: 46203 | C80: Round of 32 | D80: Mexico | E80: Ecuador | F80: 2 | G80: 0 | I80: =IF(OR(F80="",G80=""),"",F80-G80) -> 2 | J80: =IF(TRIM(C80)="Group stage",0,1) -> 1
A81: 80 | B81: 46204 | C81: Round of 32 | D81: England | E81: Congo DR | F81: 2 | G81: 1 | I81: =IF(OR(F81="",G81=""),"",F81-G81) -> 1 | J81: =IF(TRIM(C81)="Group stage",0,1) -> 1
A82: 81 | B82: 46204 | C82: Round of 32 | D82: Belgium | E82: Senegal | F82: 3 | G82: 2 | I82: =IF(OR(F82="",G82=""),"",F82-G82) -> 1 | J82: =IF(TRIM(C82)="Group stage",0,1) -> 1
A83: 82 | B83: 46204 | C83: Round of 32 | D83: USA | E83: Bosnia and Herzegovina | F83: 2 | G83: 0 | I83: =IF(OR(F83="",G83=""),"",F83-G83) -> 2 | J83: =IF(TRIM(C83)="Group stage",0,1) -> 1
A84: 83 | B84: 46205 | C84: Round of 32 | D84: Spain | E84: Austria | F84: 3 | G84: 0 | I84: =IF(OR(F84="",G84=""),"",F84-G84) -> 3 | J84: =IF(TRIM(C84)="Group stage",0,1) -> 1
A85: 84 | B85: 46205 | C85: Round of 32 | D85: Portugal | E85: Croatia | F85: 2 | G85: 1 | I85: =IF(OR(F85="",G85=""),"",F85-G85) -> 1 | J85: =IF(TRIM(C85)="Group stage",0,1) -> 1
A86: 85 | B86: 46205 | C86: Round of 32 | D86: Switzerland | E86: Algeria | F86: 2 | G86: 0 | I86: =IF(OR(F86="",G86=""),"",F86-G86) -> 2 | J86: =IF(TRIM(C86)="Group stage",0,1) -> 1
A87: 86 | B87: 46206 | C87: Round of 32 | D87: Australia | E87: Egypt | F87: 1 | G87: 1 | H87: 2-4 | I87: =IF(OR(F87="",G87=""),"",F87-G87) -> 0 | J87: =IF(TRIM(C87)="Group stage",0,1) -> 1
A88: 87 | B88: 46206 | C88: Round of 32 | D88: Argentina | E88: Cabo Verde | F88: 3 | G88: 2 | I88: =IF(OR(F88="",G88=""),"",F88-G88) -> 1 | J88: =IF(TRIM(C88)="Group stage",0,1) -> 1
A89: 88 | B89: 46206 | C89: Round of 32 | D89: Colombia | E89: Ghana | F89: 1 | G89: 0 | I89: =IF(OR(F89="",G89=""),"",F89-G89) -> 1 | J89: =IF(TRIM(C89)="Group stage",0,1) -> 1
A90: 89 | B90: 46207 | C90: Round of 16 | D90: Canada | E90: Morocco | F90: 0 | G90: 3 | I90: =IF(OR(F90="",G90=""),"",F90-G90) -> -3 | J90: =IF(TRIM(C90)="Group stage",0,1) -> 1
A91: 90 | B91: 46207 | C91: Round of 16 | D91: Paraguay | E91: France | F91: 0 | G91: 1 | I91: =IF(OR(F91="",G91=""),"",F91-G91) -> -1 | J91: =IF(TRIM(C91)="Group stage",0,1) -> 1
A92: 91 | B92: 46208 | C92: Round of 16 | D92: Brazil | E92: Norway | F92: 1 | G92: 2 | I92: =IF(OR(F92="",G92=""),"",F92-G92) -> -1 | J92: =IF(TRIM(C92)="Group stage",0,1) -> 1
A93: 92 | B93: 46208 | C93: Round of 16 | D93: Mexico | E93: England | F93: 2 | G93: 3 | I93: =IF(OR(F93="",G93=""),"",F93-G93) -> -1 | J93: =IF(TRIM(C93)="Group stage",0,1) -> 1
A94: 93 | B94: 46209 | C94: Round of 16 | D94: Portugal | E94: Spain | F94: 0 | G94: 1 | I94: =IF(OR(F94="",G94=""),"",F94-G94) -> -1 | J94: =IF(TRIM(C94)="Group stage",0,1) -> 1
A95: 94 | B95: 46209 | C95: Round of 16 | D95: USA | E95: Belgium | F95: 1 | G95: 4 | I95: =IF(OR(F95="",G95=""),"",F95-G95) -> -3 | J95: =IF(TRIM(C95)="Group stage",0,1) -> 1
A96: 95 | B96: 46210 | C96: Round of 16 | D96: Argentina | E96: Egypt | F96: 3 | G96: 2 | I96: =IF(OR(F96="",G96=""),"",F96-G96) -> 1 | J96: =IF(TRIM(C96)="Group stage",0,1) -> 1
A97: 96 | B97: 46210 | C97: Round of 16 | D97: Switzerland | E97: Colombia | F97: 0 | G97: 0 | H97: 4-3 | I97: =IF(OR(F97="",G97=""),"",F97-G97) -> 0 | J97: =IF(TRIM(C97)="Group stage",0,1) -> 1
A98: 97 | B98: 46212 | C98: Quarter-finals | D98: France | E98: Morocco | F98: 2 | G98: 0 | I98: =IF(OR(F98="",G98=""),"",F98-G98) -> 2 | J98: =IF(TRIM(C98)="Group stage",0,1) -> 1
A99: 98 | B99: 46213 | C99: Quarter-finals | D99: Spain | E99: Belgium | F99: 2 | G99: 1 | I99: =IF(OR(F99="",G99=""),"",F99-G99) -> 1 | J99: =IF(TRIM(C99)="Group stage",0,1) -> 1
A100: 99 | B100: 46214 | C100: Quarter-finals | D100: Norway | E100: England | F100: 1 | G100: 2 | I100: =IF(OR(F100="",G100=""),"",F100-G100) -> -1 | J100: =IF(TRIM(C100)="Group stage",0,1) -> 1
A101: 100 | B101: 46214 | C101: Quarter-finals | D101: Argentina | E101: Switzerland | F101: 3 | G101: 1 | I101: =IF(OR(F101="",G101=""),"",F101-G101) -> 2 | J101: =IF(TRIM(C101)="Group stage",0,1) -> 1
...

Sheet Match_Stats
A1: Match No | B1: Team | C1: xG
A2: =INT((ROW()-2)/2)+1 -> 1 | B2: =IF(ISEVEN(ROW()),INDEX(Matches!$D$2:$D$105,MATCH(A2,Matches!$A$2:$A$105,0)),INDEX(Matches!$E$2:$E$105,MATCH(A2,Matches!$A$2:$A$105,0))) -> Mexico | C2: 1.46
A3: =INT((ROW()-2)/2)+1 -> 1 | B3: =IF(ISEVEN(ROW()),INDEX(Matches!$D$2:$D$105,MATCH(A3,Matches!$A$2:$A$105,0)),INDEX(Matches!$E$2:$E$105,MATCH(A3,Matches!$A$2:$A$105,0))) -> South Africa | C3: 0.07
A4: =INT((ROW()-2)/2)+1 -> 2 | B4: =IF(ISEVEN(ROW()),INDEX(Matches!$D$2:$D$105,MATCH(A4,Matches!$A$2:$A$105,0)),INDEX(Matches!$E$2:$E$105,MATCH(A4,Matches!$A$2:$A$105,0))) -> Korea Republic | C4: 2.3
A5: =INT((ROW()-2)/2)+1 -> 2 | B5: =IF(ISEVEN(ROW()),INDEX(Matches!$D$2:$D$105,MATCH(A5,Matches!$A$2:$A$105,0)),INDEX(Matches!$E$2:$E$105,MATCH(A5,Matches!$A$2:$A$105,0))) -> Czechia | C5: 0.83
A6: =INT((ROW()-2)/2)+1 -> 3 | B6: =IF(ISEVEN(ROW()),INDEX(Matches!$D$2:$D$105,MATCH(A6,Matches!$A$2:$A$105,0)),INDEX(Matches!$E$2:$E$105,MATCH(A6,Matches!$A$2:$A$105,0))) -> Canada | C6: 1.25
A7: =INT((ROW()-2)/2)+1 -> 3 | B7: =IF(ISEVEN(ROW()),INDEX(Matches!$D$2:$D$105,MATCH(A7,Matches!$A$2:$A$105,0)),INDEX(Matches!$E$2:$E$105,MATCH(A7,Matches!$A$2:$A$105,0))) -> Bosnia and Herzegovina | C7: 0.98
A8: =INT((ROW()-2)/2)+1 -> 4 | B8: =IF(ISEVEN(ROW()),INDEX(Matches!$D$2:$D$105,MATCH(A8,Matches!$A$2:$A$105,0)),INDEX(Matches!$E$2:$E$105,MATCH(A8,Matches!$A$2:$A$105,0))) -> USA | C8: 1.42
A9: =INT((ROW()-2)/2)+1 -> 4 | B9: =IF(ISEVEN(ROW()),INDEX(Matches!$D$2:$D$105,MATCH(A9,Matches!$A$2:$A$105,0)),INDEX(Matches!$E$2:$E$105,MATCH(A9,Matches!$A$2:$A$105,0))) -> Paraguay | C9: 0.54
A10: =INT((ROW()-2)/2)+1 -> 5 | B10: =IF(ISEVEN(ROW()),INDEX(Matches!$D$2:$D$105,MATCH(A10,Matches!$A$2:$A$105,0)),INDEX(Matches!$E$2:$E$105,MATCH(A10,Matches!$A$2:$A$105,0))) -> Qatar | C10: 0.6
A11: =INT((ROW()-2)/2)+1 -> 5 | B11: =IF(ISEVEN(ROW()),INDEX(Matches!$D$2:$D$105,MATCH(A11,Matches!$A$2:$A$105,0)),INDEX(Matches!$E$2:$E$105,MATCH(A11,Matches!$A$2:$A$105,0))) -> Switzerland | C11: 3.2
A12: =INT((ROW()-2)/2)+1 -> 6 | B12: =IF(ISEVEN(ROW()),INDEX(Matches!$D$2:$D$105,MATCH(A12,Matches!$A$2:$A$105,0)),INDEX(Matches!$E$2:$E$105,MATCH(A12,Matches!$A$2:$A$105,0))) -> Brazil | C12: 1.26
A13: =INT((ROW()-2)/2)+1 -> 6 | B13: =IF(ISEVEN(ROW()),INDEX(Matches!$D$2:$D$105,MATCH(A13,Matches!$A$2:$A$105,0)),INDEX(Matches!$E$2:$E$105,MATCH(A13,Matches!$A$2:$A$105,0))) -> Morocco | C13: 1.37
... A107: =INT((ROW()-2)/2)+1 -> 53 | B107: =IF(ISEVEN(ROW()),INDEX(Matches!$D$2:$D$105,MATCH(A107,Matches!$A$2:$A$105,0)),INDEX(Matches!$E$2:$E$105,MATCH(A107,Matches!$A$2:$A$105,0))) -> Korea Republic | C107: 0.9
A108: =INT((ROW()-2)/2)+1 -> 54 | B108: =IF(ISEVEN(ROW()),INDEX(Matches!$D$2:$D$105,MATCH(A108,Matches!$A$2:$A$105,0)),INDEX(Matches!$E$2:$E$105,MATCH(A108,Matches!$A$2:$A$105,0))) -> Czechia
A109: =INT((ROW()-2)/2)+1 -> 54 | B109: =IF(ISEVEN(ROW()),INDEX(Matches!$D$2:$D$105,MATCH(A109,Matches!$A$2:$A$105,0)),INDEX(Matches!$E$2:$E$105,MATCH(A109,Matches!$A$2:$A$105,0))) -> Mexico
A110: =INT((ROW()-2)/2)+1 -> 55 | B110: =IF(ISEVEN(ROW()),INDEX(Matches!$D$2:$D$105,MATCH(A110,Matches!$A$2:$A$105,0)),INDEX(Matches!$E$2:$E$105,MATCH(A110,Matches!$A$2:$A$105,0))) -> Curaçao | C110: 0.5
A111: =INT((ROW()-2)/2)+1 -> 55 | B111: =IF(ISEVEN(ROW()),INDEX(Matches!$D$2:$D$105,MATCH(A111,Matches!$A$2:$A$105,0)),INDEX(Matches!$E$2:$E$105,MATCH(A111,Matches!$A$2:$A$105,0))) -> Côte d'Ivoire | C111: 1.31
A112: =INT((ROW()-2)/2)+1 -> 56 | B112: =IF(ISEVEN(ROW()),INDEX(Matches!$D$2:$D$105,MATCH(A112,Matches!$A$2:$A$105,0)),INDEX(Matches!$E$2:$E$105,MATCH(A112,Matches!$A$2:$A$105,0))) -> Ecuador | C112: 1.27
A113: =INT((ROW()-2)/2)+1 -> 56 | B113: =IF(ISEVEN(ROW()),INDEX(Matches!$D$2:$D$105,MATCH(A113,Matches!$A$2:$A$105,0)),INDEX(Matches!$E$2:$E$105,MATCH(A113,Matches!$A$2:$A$105,0))) -> Germany | C113: 0.65
A114: =INT((ROW()-2)/2)+1 -> 57 | B114: =IF(ISEVEN(ROW()),INDEX(Matches!$D$2:$D$105,MATCH(A114,Matches!$A$2:$A$105,0)),INDEX(Matches!$E$2:$E$105,MATCH(A114,Matches!$A$2:$A$105,0))) -> Tunisia | C114: 0.62
A115: =INT((ROW()-2)/2)+1 -> 57 | B115: =IF(ISEVEN(ROW()),INDEX(Matches!$D$2:$D$105,MATCH(A115,Matches!$A$2:$A$105,0)),INDEX(Matches!$E$2:$E$105,MATCH(A115,Matches!$A$2:$A$105,0))) -> Netherlands | C115: 1.85
A116: =INT((ROW()-2)/2)+1 -> 58 | B116: =IF(ISEVEN(ROW()),INDEX(Matches!$D$2:$D$105,MATCH(A116,Matches!$A$2:$A$105,0)),INDEX(Matches!$E$2:$E$105,MATCH(A116,Matches!$A$2:$A$105,0))) -> Japan
A117: =INT((ROW()-2)/2)+1 -> 58 | B117: =IF(ISEVEN(ROW()),INDEX(Matches!$D$2:$D$105,MATCH(A117,Matches!$A$2:$A$105,0)),INDEX(Matches!$E$2:$E$105,MATCH(A117,Matches!$A$2:$A$105,0))) -> Sweden
A118: =INT((ROW()-2)/2)+1 -> 59 | B118: =IF(ISEVEN(ROW()),INDEX(Matches!$D$2:$D$105,MATCH(A118,Matches!$A$2:$A$105,0)),INDEX(Matches!$E$2:$E$105,MATCH(A118,Matches!$A$2:$A$105,0))) -> Türkiye | C118: 3.01
A119: =INT((ROW()-2)/2)+1 -> 59 | B119: =IF(ISEVEN(ROW()),INDEX(Matches!$D$2:$D$105,MATCH(A119,Matches!$A$2:$A$105,0)),INDEX(Matches!$E$2:$E$105,MATCH(A119,Matches!$A$2:$A$105,0))) -> USA | C119: 2.13
A120: =INT((ROW()-2)/2)+1 -> 60 | B120: =IF(ISEVEN(ROW()),INDEX(Matches!$D$2:$D$105,MATCH(A120,Matches!$A$2:$A$105,0)),INDEX(Matches!$E$2:$E$105,MATCH(A120,Matches!$A$2:$A$105,0))) -> Paraguay | C120: 0.24
A121: =INT((ROW()-2)/2)+1 -> 60 | B121: =IF(ISEVEN(ROW()),INDEX(Matches!$D$2:$D$105,MATCH(A121,Matches!$A$2:$A$105,0)),INDEX(Matches!$E$2:$E$105,MATCH(A121,Matches!$A$2:$A$105,0))) -> Australia | C121: 0.55
A122: =INT((ROW()-2)/2)+1 -> 61 | B122: =IF(ISEVEN(ROW()),INDEX(Matches!$D$2:$D$105,MATCH(A122,Matches!$A$2:$A$105,0)),INDEX(Matches!$E$2:$E$105,MATCH(A122,Matches!$A$2:$A$105,0))) -> Norway | C122: 1.7
A123: =INT((ROW()-2)/2)+1 -> 61 | B123: =IF(ISEVEN(ROW()),INDEX(Matches!$D$2:$D$105,MATCH(A123,Matches!$A$2:$A$105,0)),INDEX(Matches!$E$2:$E$105,MATCH(A123,Matches!$A$2:$A$105,0))) -> France | C123: 1.5
A124: =INT((ROW()-2)/2)+1 -> 62 | B124: =IF(ISEVEN(ROW()),INDEX(Matches!$D$2:$D$105,MATCH(A124,Matches!$A$2:$A$105,0)),INDEX(Matches!$E$2:$E$105,MATCH(A124,Matches!$A$2:$A$105,0))) -> Senegal | C124: 3.01
A125: =INT((ROW()-2)/2)+1 -> 62 | B125: =IF(ISEVEN(ROW()),INDEX(Matches!$D$2:$D$105,MATCH(A125,Matches!$A$2:$A$105,0)),INDEX(Matches!$E$2:$E$105,MATCH(A125,Matches!$A$2:$A$105,0))) -> Iraq | C125: 1.04
A126: =INT((ROW()-2)/2)+1 -> 63 | B126: =IF(ISEVEN(ROW()),INDEX(Matches!$D$2:$D$105,MATCH(A126,Matches!$A$2:$A$105,0)),INDEX(Matches!$E$2:$E$105,MATCH(A126,Matches!$A$2:$A$105,0))) -> Uruguay | C126: 0.2
A127: =INT((ROW()-2)/2)+1 -> 63 | B127: =IF(ISEVEN(ROW()),INDEX(Matches!$D$2:$D$105,MATCH(A127,Matches!$A$2:$A$105,0)),INDEX(Matches!$E$2:$E$105,MATCH(A127,Matches!$A$2:$A$105,0))) -> Spain | C127: 0.86
A128: =INT((ROW()-2)/2)+1 -> 64 | B128: =IF(ISEVEN(ROW()),INDEX(Matches!$D$2:$D$105,MATCH(A128,Matches!$A$2:$A$105,0)),INDEX(Matches!$E$2:$E$105,MATCH(A128,Matches!$A$2:$A$105,0))) -> Cabo Verde | C128: 1.39
A129: =INT((ROW()-2)/2)+1 -> 64 | B129: =IF(ISEVEN(ROW()),INDEX(Matches!$D$2:$D$105,MATCH(A129,Matches!$A$2:$A$105,0)),INDEX(Matches!$E$2:$E$105,MATCH(A129,Matches!$A$2:$A$105,0))) -> Saudi Arabia | C129: 0.39
... A205: =INT((ROW()-2)/2)+1 -> 102 | B205: =IF(ISEVEN(ROW()),INDEX(Matches!$D$2:$D$105,MATCH(A205,Matches!$A$2:$A$105,0)),INDEX(Matches!$E$2:$E$105,MATCH(A205,Matches!$A$2:$A$105,0))) -> Argentina | C205: 1.84
A206: =INT((ROW()-2)/2)+1 -> 103 | B206: =IF(ISEVEN(ROW()),INDEX(Matches!$D$2:$D$105,MATCH(A206,Matches!$A$2:$A$105,0)),INDEX(Matches!$E$2:$E$105,MATCH(A206,Matches!$A$2:$A$105,0))) -> France
A207: =INT((ROW()-2)/2)+1 -> 103 | B207: =IF(ISEVEN(ROW()),INDEX(Matches!$D$2:$D$105,MATCH(A207,Matches!$A$2:$A$105,0)),INDEX(Matches!$E$2:$E$105,MATCH(A207,Matches!$A$2:$A$105,0))) -> England
A208: =INT((ROW()-2)/2)+1 -> 104 | B208: =IF(ISEVEN(ROW()),INDEX(Matches!$D$2:$D$105,MATCH(A208,Matches!$A$2:$A$105,0)),INDEX(Matches!$E$2:$E$105,MATCH(A208,Matches!$A$2:$A$105,0))) -> Spain | C208: 2.29
...

Sheet Constants
A1: Constant | B1: Value | D1: WC2022_Goals
D2: 15
A3: WC2022_avg_goals_per_team_match | B3: =SUM(D2:D33)/128 -> 1.328125 | D3: 3
D4: 1
D5: 8
D6: 4
D7: 1
D8: 3
D9: 8
D10: 1
D11: 4
D12: 13
D13: 16
D14: 6
D15: 5
... D33: 1

Sheet Split
A1: Match No | B1: Stage | C1: Set_80_20 | D1: Set_70_30
A2: 1 | B2: Group stage | C2: Test | D2: Test
A3: 2 | B3: Group stage | C3: Train | D3: Train
A4: 3 | B4: Group stage | C4: Test | D4: Test
A5: 4 | B5: Group stage | C5: Train | D5: Train
A6: 5 | B6: Group stage | C6: Test | D6: Test
A7: 6 | B7: Group stage | C7: Train | D7: Train
A8: 7 | B8: Group stage | C8: Train | D8: Train
A9: 8 | B9: Group stage | C9: Train | D9: Test
A10: 9 | B10: Group stage | C10: Train | D10: Train
A11: 10 | B11: Group stage | C11: Train | D11: Train
A12: 11 | B12: Group stage | C12: Train | D12: Train
A13: 12 | B13: Group stage | C13: Train | D13: Train
... A20: 19 | B20: Group stage | C20: Test | D20: Test
A21: 20 | B21: Group stage | C21: Train | D21: Train | E21: =COUNTIF(C2:C105,"Test") -> 21
A22: 21 | B22: Group stage | C22: Train | D22: Train
A23: 22 | B23: Group stage | C23: Test | D23: Test
A24: 23 | B24: Group stage | C24: Train | D24: Train | E24: =COUNTIF(D2:D105,"Test") -> 31
A25: 24 | B25: Group stage | C25: Train | D25: Train
A26: 25 | B26: Group stage | C26: Test | D26: Test
A27: 26 | B27: Group stage | C27: Test | D27: Test
A28: 27 | B28: Group stage | C28: Train | D28: Test
A29: 28 | B29: Group stage | C29: Test | D29: Test
A30: 29 | B30: Group stage | C30: Test | D30: Test
A31: 30 | B31: Group stage | C31: Train | D31: Train
A32: 31 | B32: Group stage | C32: Train | D32: Train
A33: 32 | B33: Group stage | C33: Train | D33: Train
A34: 33 | B34: Group stage | C34: Train | D34: Train
A35: 34 | B35: Group stage | C35: Test | D35: Test
A36: 35 | B36: Group stage | C36: Train | D36: Train
... A105: 104 | B105: Final | C105: Test | D105: Test

Sheet WC2022 Squad_Standard_Stats
E1: Playing Time | I1: Performance | Q1: Per 90 Minutes
A2: Squad | B2: # Pl | C2: Age | D2: Poss | E2: MP | F2: Starts | G2: Min | H2: 90s | I2: Gls | J2: Ast | K2: G+A | L2: G-PK | M2: PK | N2: PKatt | O2: CrdY | P2: CrdR | Q2: Gls | R2: Ast | S2: G+A | T2: G-PK | U2: G+A-PK
A3: ar Argentina | B3: 24 | C3: 27.5 | D3: 57.4 | E3: 7 | F3: 77 | G3: 690 | H3: 7.7 | I3: 15 | J3: 8 | K3: 23 | L3: 11 | M3: 4 | N3: 5 | O3: 19 | P3: 0 | Q3: 1.96 | R3: 1.04 | S3: 3 | T3: 1.43 | U3: 2.48
A4: au Australia | B4: 20 | C4: 27.8 | D4: 37.8 | E4: 4 | F4: 44 | G4: 360 | H4: 4 | I4: 3 | J4: 3 | K4: 6 | L4: 3 | M4: 0 | N4: 0 | O4: 7 | P4: 0 | Q4: 0.75 | R4: 0.75 | S4: 1.5 | T4: 0.75 | U4: 1.5
A5: be Belgium | B5: 20 | C5: 29.7 | D5: 57 | E5: 3 | F5: 33 | G5: 270 | H5: 3 | I5: 1 | J5: 1 | K5: 2 | L5: 1 | M5: 0 | N5: 0 | O5: 5 | P5: 0 | Q5: 0.33 | R5: 0.33 | S5: 0.67 | T5: 0.33 | U5: 0.67
A6: br Brazil | B6: 26 | C6: 27.6 | D6: 56.2 | E6: 5 | F6: 55 | G6: 480 | H6: 5.3 | I6: 8 | J6: 6 | K6: 14 | L6: 7 | M6: 1 | N6: 1 | O6: 6 | P6: 0 | Q6: 1.5 | R6: 1.13 | S6: 2.62 | T6: 1.31 | U6: 2.44
A7: cm Cameroon | B7: 22 | C7: 27.2 | D7: 41.7 | E7: 3 | F7: 33 | G7: 270 | H7: 3 | I7: 4 | J7: 4 | K7: 8 | L7: 4 | M7: 0 | N7: 0 | O7: 8 | P7: 1 | Q7: 1.33 | R7: 1.33 | S7: 2.67 | T7: 1.33 | U7: 2.67
A8: ca Canada | B8: 19 | C8: 27.3 | D8: 52 | E8: 3 | F8: 33 | G8: 270 | H8: 3 | I8: 1 | J8: 1 | K8: 2 | L8: 1 | M8: 0 | N8: 1 | O8: 8 | P8: 0 | Q8: 0.33 | R8: 0.33 | S8: 0.67 | T8: 0.33 | U8: 0.67
A9: cr Costa Rica | B9: 22 | C9: 29.7 | D9: 31.3 | E9: 3 | F9: 33 | G9: 270 | H9: 3 | I9: 3 | J9: 1 | K9: 4 | L9: 3 | M9: 0 | N9: 0 | O9: 6 | P9: 0 | Q9: 1 | R9: 0.33 | S9: 1.33 | T9: 1 | U9: 1.33
A10: hr Croatia | B10: 21 | C10: 28.3 | D10: 54.3 | E10: 7 | F10: 77 | G10: 690 | H10: 7.7 | I10: 8 | J10: 8 | K10: 16 | L10: 8 | M10: 0 | N10: 0 | O10: 8 | P10: 0 | Q10: 1.04 | R10: 1.04 | S10: 2.09 | T10: 1.04 | U10: 2.09
A11: dk Denmark | B11: 20 | C11: 26.6 | D11: 60 | E11: 3 | F11: 33 | G11: 270 | H11: 3 | I11: 1 | J11: 1 | K11: 2 | L11: 1 | M11: 0 | N11: 0 | O11: 5 | P11: 0 | Q11: 0.33 | R11: 0.33 | S11: 0.67 | T11: 0.33 | U11: 0.67
A12: ec Ecuador | B12: 18 | C12: 24.9 | D12: 53.3 | E12: 3 | F12: 33 | G12: 270 | H12: 3 | I12: 4 | J12: 2 | K12: 6 | L12: 3 | M12: 1 | N12: 1 | O12: 3 | P12: 0 | Q12: 1.33 | R12: 0.67 | S12: 2 | T12: 1 | U12: 1.67
A13: eng England | B13: 20 | C13: 26.1 | D13: 62.8 | E13: 5 | F13: 55 | G13: 450 | H13: 5 | I13: 13 | J13: 11 | K13: 24 | L13: 12 | M13: 1 | N13: 2 | O13: 1 | P13: 0 | Q13: 2.6 | R13: 2.2 | S13: 4.8 | T13: 2.4 | U13: 4.6
A14: fr France | B14: 24 | C14: 26.3 | D14: 51.3 | E14: 7 | F14: 77 | G14: 660 | H14: 7.3 | I14: 16 | J14: 12 | K14: 28 | L14: 14 | M14: 2 | N14: 2 | O14: 8 | P14: 0 | Q14: 2.18 | R14: 1.64 | S14: 3.82 | T14: 1.91 | U14: 3.55
... A34: wls Wales | B34: 18 | C34: 26.8 | D34: 46.7 | E34: 3 | F34: 33 | G34: 270 | H34: 3 | I34: 1 | J34: 0 | K34: 1 | L34: 0 | M34: 1 | N34: 1 | O34: 5 | P34: 1 | Q34: 0.33 | R34: 0 | S34: 0.33 | T34: 0 | U34: 0

Sheet Raw_Matches
A1: Round | B1: Wk | C1: Day | D1: Date | E1: Time | F1: Home | G1: Score | H1: Away | I1: Attendance | J1: Venue | K1: Referee | L1: Match Report | M1: Notes | N1: Goals_A | O1: Goals_B | P1: Shootout
A2: Group stage | B2: 1 | C2: Thu | D2: 46184 | E2: 13:00 (04:30) | F2: Mexico mx | G2: 2–0 | H2: za South Africa | I2: 80824 | J2: Estadio Banorte (Neutral Site) | K2: Wilton Sampaio | L2: Match Report | N2: =VALUE(TRIM(RIGHT(LEFT(SUBSTITUTE(G2,_xlfn.UNICHAR(8211),"-"),FIND("-",SUBSTITUTE(G2,_xlfn.UNICHAR(8211),"-"))-1),2))) -> 2 | O2: =VALUE(TRIM(LEFT(MID(SUBSTITUTE(G2,_xlfn.UNICHAR(8211),"-"),FIND("-",SUBSTITUTE(G2,_xlfn.UNICHAR(8211),"-"))+1,100),2))) -> 0 | P2: =IF(LEFT(TRIM(G2),1)="(",MID(TRIM(G2),2,FIND(")",TRIM(G2))-2)&"-"&MID(TRIM(G2),FIND("(",TRIM(G2),2)+1,LEN(TRIM(G2))-FIND("(",TRIM(G2),2)-1),"")
A3: Group stage | B3: 1 | C3: Thu | D3: 46184 | E3: 20:00 (11:30) | F3: Korea Republic kr | G3: 2–1 | H3: cz Czechia | I3: 44985 | J3: Estadio Akron (Neutral Site) | K3: Amin Omar | L3: Match Report | N3: =VALUE(TRIM(RIGHT(LEFT(SUBSTITUTE(G3,_xlfn.UNICHAR(8211),"-"),FIND("-",SUBSTITUTE(G3,_xlfn.UNICHAR(8211),"-"))-1),2))) -> 2 | O3: =VALUE(TRIM(LEFT(MID(SUBSTITUTE(G3,_xlfn.UNICHAR(8211),"-"),FIND("-",SUBSTITUTE(G3,_xlfn.UNICHAR(8211),"-"))+1,100),2))) -> 1 | P3: =IF(LEFT(TRIM(G3),1)="(",MID(TRIM(G3),2,FIND(")",TRIM(G3))-2)&"-"&MID(TRIM(G3),FIND("(",TRIM(G3),2)+1,LEN(TRIM(G3))-FIND("(",TRIM(G3),2)-1),"")
A4: Group stage | B4: 1 | C4: Fri | D4: 46185 | E4: 15:00 (04:30) | F4: Canada ca | G4: 1–1 | H4: ba Bosnia–Herz | I4: 43002 | J4: BMO Field (Neutral Site) | K4: Facundo Tello | L4: Match Report | N4: =VALUE(TRIM(RIGHT(LEFT(SUBSTITUTE(G4,_xlfn.UNICHAR(8211),"-"),FIND("-",SUBSTITUTE(G4,_xlfn.UNICHAR(8211),"-"))-1),2))) -> 1 | O4: =VALUE(TRIM(LEFT(MID(SUBSTITUTE(G4,_xlfn.UNICHAR(8211),"-"),FIND("-",SUBSTITUTE(G4,_xlfn.UNICHAR(8211),"-"))+1,100),2))) -> 1 | P4: =IF(LEFT(TRIM(G4),1)="(",MID(TRIM(G4),2,FIND(")",TRIM(G4))-2)&"-"&MID(TRIM(G4),FIND("(",TRIM(G4),2)+1,LEN(TRIM(G4))-FIND("(",TRIM(G4),2)-1),"")
A5: Group stage | B5: 1 | C5: Fri | D5: 46185 | E5: 18:00 (10:30) | F5: USA us | G5: 4–1 | H5: py Paraguay | I5: 70492 | J5: SoFi Stadium (Neutral Site) | K5: Danny Makkelie | L5: Match Report | N5: =VALUE(TRIM(RIGHT(LEFT(SUBSTITUTE(G5,_xlfn.UNICHAR(8211),"-"),FIND("-",SUBSTITUTE(G5,_xlfn.UNICHAR(8211),"-"))-1),2))) -> 4 | O5: =VALUE(TRIM(LEFT(MID(SUBSTITUTE(G5,_xlfn.UNICHAR(8211),"-"),FIND("-",SUBSTITUTE(G5,_xlfn.UNICHAR(8211),"-"))+1,100),2))) -> 1 | P5: =IF(LEFT(TRIM(G5),1)="(",MID(TRIM(G5),2,FIND(")",TRIM(G5))-2)&"-"&MID(TRIM(G5),FIND("(",TRIM(G5),2)+1,LEN(TRIM(G5))-FIND("(",TRIM(G5),2)-1),"")
A6: Group stage | B6: 1 | C6: Sat | D6: 46186 | E6: 12:00 (04:30) | F6: Qatar qa | G6: 1–1 | H6: ch Switzerland | I6: 67966 | J6: Levi's Stadium (Neutral Site) | K6: Said Martínez | L6: Match Report | N6: =VALUE(TRIM(RIGHT(LEFT(SUBSTITUTE(G6,_xlfn.UNICHAR(8211),"-"),FIND("-",SUBSTITUTE(G6,_xlfn.UNICHAR(8211),"-"))-1),2))) -> 1 | O6: =VALUE(TRIM(LEFT(MID(SUBSTITUTE(G6,_xlfn.UNICHAR(8211),"-"),FIND("-",SUBSTITUTE(G6,_xlfn.UNICHAR(8211),"-"))+1,100),2))) -> 1 | P6: =IF(LEFT(TRIM(G6),1)="(",MID(TRIM(G6),2,FIND(")",TRIM(G6))-2)&"-"&MID(TRIM(G6),FIND("(",TRIM(G6),2)+1,LEN(TRIM(G6))-FIND("(",TRIM(G6),2)-1),"")
A7: Group stage | B7: 1 | C7: Sat | D7: 46186 | E7: 18:00 (07:30) | F7: Brazil br | G7: 1–1 | H7: ma Morocco | I7: 80663 | J7: MetLife Stadium (Neutral Site) | K7: Slavko Vinčič | L7: Match Report | N7: =VALUE(TRIM(RIGHT(LEFT(SUBSTITUTE(G7,_xlfn.UNICHAR(8211),"-"),FIND("-",SUBSTITUTE(G7,_xlfn.UNICHAR(8211),"-"))-1),2))) -> 1 | O7: =VALUE(TRIM(LEFT(MID(SUBSTITUTE(G7,_xlfn.UNICHAR(8211),"-"),FIND("-",SUBSTITUTE(G7,_xlfn.UNICHAR(8211),"-"))+1,100),2))) -> 1 | P7: =IF(LEFT(TRIM(G7),1)="(",MID(TRIM(G7),2,FIND(")",TRIM(G7))-2)&"-"&MID(TRIM(G7),FIND("(",TRIM(G7),2)+1,LEN(TRIM(G7))-FIND("(",TRIM(G7),2)-1),"")
A8: Group stage | B8: 1 | C8: Sat | D8: 46186 | E8: 21:00 (13:30) | F8: Australia au | G8: 2–0 | H8: tr Türkiye | I8: 52497 | J8: BC Place Stadium (Neutral Site) | K8: Jesús Valenzuela | L8: Match Report | N8: =VALUE(TRIM(RIGHT(LEFT(SUBSTITUTE(G8,_xlfn.UNICHAR(8211),"-"),FIND("-",SUBSTITUTE(G8,_xlfn.UNICHAR(8211),"-"))-1),2))) -> 2 | O8: =VALUE(TRIM(LEFT(MID(SUBSTITUTE(G8,_xlfn.UNICHAR(8211),"-"),FIND("-",SUBSTITUTE(G8,_xlfn.UNICHAR(8211),"-"))+1,100),2))) -> 0 | P8: =IF(LEFT(TRIM(G8),1)="(",MID(TRIM(G8),2,FIND(")",TRIM(G8))-2)&"-"&MID(TRIM(G8),FIND("(",TRIM(G8),2)+1,LEN(TRIM(G8))-FIND("(",TRIM(G8),2)-1),"")
A9: Group stage | B9: 1 | C9: Sat | D9: 46186 | E9: 21:00 (10:30) | F9: Haiti ht | G9: 0–1 | H9: sct Scotland | I9: 64146 | J9: Gillette Stadium (Neutral Site) | K9: Mustapha Ghorbal | L9: Match Report | N9: =VALUE(TRIM(RIGHT(LEFT(SUBSTITUTE(G9,_xlfn.UNICHAR(8211),"-"),FIND("-",SUBSTITUTE(G9,_xlfn.UNICHAR(8211),"-"))-1),2))) -> 0 | O9: =VALUE(TRIM(LEFT(MID(SUBSTITUTE(G9,_xlfn.UNICHAR(8211),"-"),FIND("-",SUBSTITUTE(G9,_xlfn.UNICHAR(8211),"-"))+1,100),2))) -> 1 | P9: =IF(LEFT(TRIM(G9),1)="(",MID(TRIM(G9),2,FIND(")",TRIM(G9))-2)&"-"&MID(TRIM(G9),FIND("(",TRIM(G9),2)+1,LEN(TRIM(G9))-FIND("(",TRIM(G9),2)-1),"")
A10: Group stage | B10: 1 | C10: Sun | D10: 46187 | E10: 12:00 (02:30) | F10: Germany de | G10: 7–1 | H10: cw Curaçao | I10: 68021 | J10: Reliant Stadium (Neutral Site) | K10: Jalal Jiyed | L10: Match Report | N10: =VALUE(TRIM(RIGHT(LEFT(SUBSTITUTE(G10,_xlfn.UNICHAR(8211),"-"),FIND("-",SUBSTITUTE(G10,_xlfn.UNICHAR(8211),"-"))-1),2))) -> 7 | O10: =VALUE(TRIM(LEFT(MID(SUBSTITUTE(G10,_xlfn.UNICHAR(8211),"-"),FIND("-",SUBSTITUTE(G10,_xlfn.UNICHAR(8211),"-"))+1,100),2))) -> 1 | P10: =IF(LEFT(TRIM(G10),1)="(",MID(TRIM(G10),2,FIND(")",TRIM(G10))-2)&"-"&MID(TRIM(G10),FIND("(",TRIM(G10),2)+1,LEN(TRIM(G10))-FIND("(",TRIM(G10),2)-1),"")
A11: Group stage | B11: 1 | C11: Sun | D11: 46187 | E11: 15:00 (05:30) | F11: Netherlands nl | G11: 2–2 | H11: jp Japan | I11: 69285 | J11: AT&T Stadium (Neutral Site) | K11: Ismail Elfath | L11: Match Report | N11: =VALUE(TRIM(RIGHT(LEFT(SUBSTITUTE(G11,_xlfn.UNICHAR(8211),"-"),FIND("-",SUBSTITUTE(G11,_xlfn.UNICHAR(8211),"-"))-1),2))) -> 2 | O11: =VALUE(TRIM(LEFT(MID(SUBSTITUTE(G11,_xlfn.UNICHAR(8211),"-"),FIND("-",SUBSTITUTE(G11,_xlfn.UNICHAR(8211),"-"))+1,100),2))) -> 2 | P11: =IF(LEFT(TRIM(G11),1)="(",MID(TRIM(G11),2,FIND(")",TRIM(G11))-2)&"-"&MID(TRIM(G11),FIND("(",TRIM(G11),2)+1,LEN(TRIM(G11))-FIND("(",TRIM(G11),2)-1),"")
A12: Group stage | B12: 1 | C12: Sun | D12: 46187 | E12: 19:00 (08:30) | F12: Côte d'Ivoire ci | G12: 1–0 | H12: ec Ecuador | I12: 68274 | J12: Lincoln Financial Field (Neutral Site) | K12: François Letexier | L12: Match Report | N12: =VALUE(TRIM(RIGHT(LEFT(SUBSTITUTE(G12,_xlfn.UNICHAR(8211),"-"),FIND("-",SUBSTITUTE(G12,_xlfn.UNICHAR(8211),"-"))-1),2))) -> 1 | O12: =VALUE(TRIM(LEFT(MID(SUBSTITUTE(G12,_xlfn.UNICHAR(8211),"-"),FIND("-",SUBSTITUTE(G12,_xlfn.UNICHAR(8211),"-"))+1,100),2))) -> 0 | P12: =IF(LEFT(TRIM(G12),1)="(",MID(TRIM(G12),2,FIND(")",TRIM(G12))-2)&"-"&MID(TRIM(G12),FIND("(",TRIM(G12),2)+1,LEN(TRIM(G12))-FIND("(",TRIM(G12),2)-1),"")
A13: Group stage | B13: 1 | C13: Sun | D13: 46187 | E13: 20:00 (11:30) | F13: Sweden se | G13: 5–1 | H13: tn Tunisia | I13: 50987 | J13: Estadio BBVA (Neutral Site) | K13: Yael Falcón | L13: Match Report | N13: =VALUE(TRIM(RIGHT(LEFT(SUBSTITUTE(G13,_xlfn.UNICHAR(8211),"-"),FIND("-",SUBSTITUTE(G13,_xlfn.UNICHAR(8211),"-"))-1),2))) -> 5 | O13: =VALUE(TRIM(LEFT(MID(SUBSTITUTE(G13,_xlfn.UNICHAR(8211),"-"),FIND("-",SUBSTITUTE(G13,_xlfn.UNICHAR(8211),"-"))+1,100),2))) -> 1 | P13: =IF(LEFT(TRIM(G13),1)="(",MID(TRIM(G13),2,FIND(")",TRIM(G13))-2)&"-"&MID(TRIM(G13),FIND("(",TRIM(G13),2)+1,LEN(TRIM(G13))-FIND("(",TRIM(G13),2)-1),"")
... A73: Group stage | B73: 3 | C73: Sat | D73: 46200 | E73: 21:00 (11:30) | F73: Algeria dz | G73: 3–3 | H73: at Austria | I73: 69045 | J73: GEHA Field at Arrowhead Stadium (Neutral Site) | K73: Ilgiz Tantashev | L73: Match Report | N73: =VALUE(TRIM(RIGHT(LEFT(SUBSTITUTE(G73,_xlfn.UNICHAR(8211),"-"),FIND("-",SUBSTITUTE(G73,_xlfn.UNICHAR(8211),"-"))-1),2))) -> 3 | O73: =VALUE(TRIM(LEFT(MID(SUBSTITUTE(G73,_xlfn.UNICHAR(8211),"-"),FIND("-",SUBSTITUTE(G73,_xlfn.UNICHAR(8211),"-"))+1,100),2))) -> 3 | P73: =IF(LEFT(TRIM(G73),1)="(",MID(TRIM(G73),2,FIND(")",TRIM(G73))-2)&"-"&MID(TRIM(G73),FIND("(",TRIM(G73),2)+1,LEN(TRIM(G73))-FIND("(",TRIM(G73),2)-1),"")
A74: Round of 32 | C74: Sun | D74: 46201 | E74: 12:00 (04:30) | F74: South Africa za | G74: 0–1 | H74: ca Canada | I74: 69237 | J74: SoFi Stadium (Neutral Site) | K74: João Pinheiro | L74: Match Report | N74: =VALUE(TRIM(RIGHT(LEFT(SUBSTITUTE(G74,_xlfn.UNICHAR(8211),"-"),FIND("-",SUBSTITUTE(G74,_xlfn.UNICHAR(8211),"-"))-1),2))) -> 0 | O74: =VALUE(TRIM(LEFT(MID(SUBSTITUTE(G74,_xlfn.UNICHAR(8211),"-"),FIND("-",SUBSTITUTE(G74,_xlfn.UNICHAR(8211),"-"))+1,100),2))) -> 1 | P74: =IF(LEFT(TRIM(G74),1)="(",MID(TRIM(G74),2,FIND(")",TRIM(G74))-2)&"-"&MID(TRIM(G74),FIND("(",TRIM(G74),2)+1,LEN(TRIM(G74))-FIND("(",TRIM(G74),2)-1),"")
A75: Round of 32 | C75: Mon | D75: 46202 | E75: 12:00 (02:30) | F75: Brazil br | G75: 2–1 | H75: jp Japan | I75: 68777 | J75: Reliant Stadium (Neutral Site) | K75: Maurizio Mariani | L75: Match Report | N75: =VALUE(TRIM(RIGHT(LEFT(SUBSTITUTE(G75,_xlfn.UNICHAR(8211),"-"),FIND("-",SUBSTITUTE(G75,_xlfn.UNICHAR(8211),"-"))-1),2))) -> 2 | O75: =VALUE(TRIM(LEFT(MID(SUBSTITUTE(G75,_xlfn.UNICHAR(8211),"-"),FIND("-",SUBSTITUTE(G75,_xlfn.UNICHAR(8211),"-"))+1,100),2))) -> 1 | P75: =IF(LEFT(TRIM(G75),1)="(",MID(TRIM(G75),2,FIND(")",TRIM(G75))-2)&"-"&MID(TRIM(G75),FIND("(",TRIM(G75),2)+1,LEN(TRIM(G75))-FIND("(",TRIM(G75),2)-1),"")
A76: Round of 32 | C76: Mon | D76: 46202 | E76: 16:30 (06:00) | F76: Germany de | G76: (3) 1–1 (4) | H76: py Paraguay | I76: 63945 | J76: Gillette Stadium (Neutral Site) | K76: Jalal Jayed | L76: Match Report | M76: Paraguay won a penalty shoot-out following extra time | N76: =VALUE(TRIM(RIGHT(LEFT(SUBSTITUTE(G76,_xlfn.UNICHAR(8211),"-"),FIND("-",SUBSTITUTE(G76,_xlfn.UNICHAR(8211),"-"))-1),2))) -> 1 | O76: =VALUE(TRIM(LEFT(MID(SUBSTITUTE(G76,_xlfn.UNICHAR(8211),"-"),FIND("-",SUBSTITUTE(G76,_xlfn.UNICHAR(8211),"-"))+1,100),2))) -> 1 | P76: =IF(LEFT(TRIM(G76),1)="(",MID(TRIM(G76),2,FIND(")",TRIM(G76))-2)&"-"&MID(TRIM(G76),FIND("(",TRIM(G76),2)+1,LEN(TRIM(G76))-FIND("(",TRIM(G76),2)-1),"") -> 3-4
A77: Round of 32 | C77: Mon | D77: 46202 | E77: 19:00 (10:30) | F77: Netherlands nl | G77: (2) 1–1 (3) | H77: ma Morocco | I77: 51243 | J77: Estadio BBVA (Neutral Site) | K77: Wilton Sampaio | L77: Match Report | M77: Morocco won a penalty shoot-out following extra time | N77: =VALUE(TRIM(RIGHT(LEFT(SUBSTITUTE(G77,_xlfn.UNICHAR(8211),"-"),FIND("-",SUBSTITUTE(G77,_xlfn.UNICHAR(8211),"-"))-1),2))) -> 1 | O77: =VALUE(TRIM(LEFT(MID(SUBSTITUTE(G77,_xlfn.UNICHAR(8211),"-"),FIND("-",SUBSTITUTE(G77,_xlfn.UNICHAR(8211),"-"))+1,100),2))) -> 1 | P77: =IF(LEFT(TRIM(G77),1)="(",MID(TRIM(G77),2,FIND(")",TRIM(G77))-2)&"-"&MID(TRIM(G77),FIND("(",TRIM(G77),2)+1,LEN(TRIM(G77))-FIND("(",TRIM(G77),2)-1),"") -> 2-3
A78: Round of 32 | C78: Tue | D78: 46203 | E78: 12:00 (02:30) | F78: Côte d'Ivoire ci | G78: 1–2 | H78: no Norway | I78: 69665 | J78: AT&T Stadium (Neutral Site) | K78: Jesús Valenzuela | L78: Match Report | N78: =VALUE(TRIM(RIGHT(LEFT(SUBSTITUTE(G78,_xlfn.UNICHAR(8211),"-"),FIND("-",SUBSTITUTE(G78,_xlfn.UNICHAR(8211),"-"))-1),2))) -> 1 | O78: =VALUE(TRIM(LEFT(MID(SUBSTITUTE(G78,_xlfn.UNICHAR(8211),"-"),FIND("-",SUBSTITUTE(G78,_xlfn.UNICHAR(8211),"-"))+1,100),2))) -> 2 | P78: =IF(LEFT(TRIM(G78),1)="(",MID(TRIM(G78),2,FIND(")",TRIM(G78))-2)&"-"&MID(TRIM(G78),FIND("(",TRIM(G78),2)+1,LEN(TRIM(G78))-FIND("(",TRIM(G78),2)-1),"")
A79: Round of 32 | C79: Tue | D79: 46203 | E79: 17:00 (06:30) | F79: France fr | G79: 3–0 | H79: se Sweden | I79: 80663 | J79: MetLife Stadium (Neutral Site) | K79: Danny Makkelie | L79: Match Report | N79: =VALUE(TRIM(RIGHT(LEFT(SUBSTITUTE(G79,_xlfn.UNICHAR(8211),"-"),FIND("-",SUBSTITUTE(G79,_xlfn.UNICHAR(8211),"-"))-1),2))) -> 3 | O79: =VALUE(TRIM(LEFT(MID(SUBSTITUTE(G79,_xlfn.UNICHAR(8211),"-"),FIND("-",SUBSTITUTE(G79,_xlfn.UNICHAR(8211),"-"))+1,100),2))) -> 0 | P79: =IF(LEFT(TRIM(G79),1)="(",MID(TRIM(G79),2,FIND(")",TRIM(G79))-2)&"-"&MID(TRIM(G79),FIND("(",TRIM(G79),2)+1,LEN(TRIM(G79))-FIND("(",TRIM(G79),2)-1),"")
A80: Round of 32 | C80: Tue | D80: 46203 | E80: 20:00 (11:30) | F80: Mexico mx | G80: 2–0 | H80: ec Ecuador | I80: 80824 | J80: Estadio Banorte (Neutral Site) | K80: Slavko Vinčič | L80: Match Report | N80: =VALUE(TRIM(RIGHT(LEFT(SUBSTITUTE(G80,_xlfn.UNICHAR(8211),"-"),FIND("-",SUBSTITUTE(G80,_xlfn.UNICHAR(8211),"-"))-1),2))) -> 2 | O80: =VALUE(TRIM(LEFT(MID(SUBSTITUTE(G80,_xlfn.UNICHAR(8211),"-"),FIND("-",SUBSTITUTE(G80,_xlfn.UNICHAR(8211),"-"))+1,100),2))) -> 0 | P80: =IF(LEFT(TRIM(G80),1)="(",MID(TRIM(G80),2,FIND(")",TRIM(G80))-2)&"-"&MID(TRIM(G80),FIND("(",TRIM(G80),2)+1,LEN(TRIM(G80))-FIND("(",TRIM(G80),2)-1),"")
A81: Round of 32 | C81: Wed | D81: 46204 | E81: 12:00 (01:30) | F81: England eng | G81: 2–1 | H81: cd Congo DR | I81: 68239 | J81: Mercedes-Benz Stadium (Neutral Site) | K81: Adham Makhadmeh | L81: Match Report | N81: =VALUE(TRIM(RIGHT(LEFT(SUBSTITUTE(G81,_xlfn.UNICHAR(8211),"-"),FIND("-",SUBSTITUTE(G81,_xlfn.UNICHAR(8211),"-"))-1),2))) -> 2 | O81: =VALUE(TRIM(LEFT(MID(SUBSTITUTE(G81,_xlfn.UNICHAR(8211),"-"),FIND("-",SUBSTITUTE(G81,_xlfn.UNICHAR(8211),"-"))+1,100),2))) -> 1 | P81: =IF(LEFT(TRIM(G81),1)="(",MID(TRIM(G81),2,FIND(")",TRIM(G81))-2)&"-"&MID(TRIM(G81),FIND("(",TRIM(G81),2)+1,LEN(TRIM(G81))-FIND("(",TRIM(G81),2)-1),"")
A82: Round of 32 | C82: Wed | D82: 46204 | E82: 13:00 (05:30) | F82: Belgium be | G82: 3–2 | H82: sn Senegal | I82: 66925 | J82: Lumen Field (Neutral Site) | K82: Said Martínez | L82: Match Report | M82: Required Extra Time | N82: =VALUE(TRIM(RIGHT(LEFT(SUBSTITUTE(G82,_xlfn.UNICHAR(8211),"-"),FIND("-",SUBSTITUTE(G82,_xlfn.UNICHAR(8211),"-"))-1),2))) -> 3 | O82: =VALUE(TRIM(LEFT(MID(SUBSTITUTE(G82,_xlfn.UNICHAR(8211),"-"),FIND("-",SUBSTITUTE(G82,_xlfn.UNICHAR(8211),"-"))+1,100),2))) -> 2 | P82: =IF(LEFT(TRIM(G82),1)="(",MID(TRIM(G82),2,FIND(")",TRIM(G82))-2)&"-"&MID(TRIM(G82),FIND("(",TRIM(G82),2)+1,LEN(TRIM(G82))-FIND("(",TRIM(G82),2)-1),"")
A83: Round of 32 | C83: Wed | D83: 46204 | E83: 17:00 (09:30) | F83: USA us | G83: 2–0 | H83: ba Bosnia–Herz | I83: 68827 | J83: Levi's Stadium (Neutral Site) | K83: Raphael Claus | L83: Match Report | N83: =VALUE(TRIM(RIGHT(LEFT(SUBSTITUTE(G83,_xlfn.UNICHAR(8211),"-"),FIND("-",SUBSTITUTE(G83,_xlfn.UNICHAR(8211),"-"))-1),2))) -> 2 | O83: =VALUE(TRIM(LEFT(MID(SUBSTITUTE(G83,_xlfn.UNICHAR(8211),"-"),FIND("-",SUBSTITUTE(G83,_xlfn.UNICHAR(8211),"-"))+1,100),2))) -> 0 | P83: =IF(LEFT(TRIM(G83),1)="(",MID(TRIM(G83),2,FIND(")",TRIM(G83))-2)&"-"&MID(TRIM(G83),FIND("(",TRIM(G83),2)+1,LEN(TRIM(G83))-FIND("(",TRIM(G83),2)-1),"")
A84: Round of 32 | C84: Thu | D84: 46205 | E84: 12:00 (04:30) | F84: Spain es | G84: 3–0 | H84: at Austria | I84: 70492 | J84: SoFi Stadium (Neutral Site) | K84: Glenn Nyberg | L84: Match Report | N84: =VALUE(TRIM(RIGHT(LEFT(SUBSTITUTE(G84,_xlfn.UNICHAR(8211),"-"),FIND("-",SUBSTITUTE(G84,_xlfn.UNICHAR(8211),"-"))-1),2))) -> 3 | O84: =VALUE(TRIM(LEFT(MID(SUBSTITUTE(G84,_xlfn.UNICHAR(8211),"-"),FIND("-",SUBSTITUTE(G84,_xlfn.UNICHAR(8211),"-"))+1,100),2))) -> 0 | P84: =IF(LEFT(TRIM(G84),1)="(",MID(TRIM(G84),2,FIND(")",TRIM(G84))-2)&"-"&MID(TRIM(G84),FIND("(",TRIM(G84),2)+1,LEN(TRIM(G84))-FIND("(",TRIM(G84),2)-1),"")
A85: Round of 32 | C85: Thu | D85: 46205 | E85: 19:00 (08:30) | F85: Portugal pt | G85: 2–1 | H85: hr Croatia | I85: 43036 | J85: BMO Field (Neutral Site) | K85: Espen Eskås | L85: Match Report | N85: =VALUE(TRIM(RIGHT(LEFT(SUBSTITUTE(G85,_xlfn.UNICHAR(8211),"-"),FIND("-",SUBSTITUTE(G85,_xlfn.UNICHAR(8211),"-"))-1),2))) -> 2 | O85: =VALUE(TRIM(LEFT(MID(SUBSTITUTE(G85,_xlfn.UNICHAR(8211),"-"),FIND("-",SUBSTITUTE(G85,_xlfn.UNICHAR(8211),"-"))+1,100),2))) -> 1 | P85: =IF(LEFT(TRIM(G85),1)="(",MID(TRIM(G85),2,FIND(")",TRIM(G85))-2)&"-"&MID(TRIM(G85),FIND("(",TRIM(G85),2)+1,LEN(TRIM(G85))-FIND("(",TRIM(G85),2)-1),"")
A86: Round of 32 | C86: Thu | D86: 46205 | E86: 20:00 (12:30) | F86: Switzerland ch | G86: 2–0 | H86: dz Algeria | I86: 52497 | J86: BC Place Stadium (Neutral Site) | K86: Yael Falcón | L86: Match Report | N86: =VALUE(TRIM(RIGHT(LEFT(SUBSTITUTE(G86,_xlfn.UNICHAR(8211),"-"),FIND("-",SUBSTITUTE(G86,_xlfn.UNICHAR(8211),"-"))-1),2))) -> 2 | O86: =VALUE(TRIM(LEFT(MID(SUBSTITUTE(G86,_xlfn.UNICHAR(8211),"-"),FIND("-",SUBSTITUTE(G86,_xlfn.UNICHAR(8211),"-"))+1,100),2))) -> 0 | P86: =IF(LEFT(TRIM(G86),1)="(",MID(TRIM(G86),2,FIND(")",TRIM(G86))-2)&"-"&MID(TRIM(G86),FIND("(",TRIM(G86),2)+1,LEN(TRIM(G86))-FIND("(",TRIM(G86),2)-1),"")
A87: Round of 32 | C87: Fri | D87: 46206 | E87: 13:00 (03:30) | F87: Australia au | G87: (2) 1–1 (4) | H87: eg Egypt | I87: 70244 | J87: AT&T Stadium (Neutral Site) | K87: Gustavo Tejera | L87: Match Report | M87: Egypt won a penalty shoot-out following extra time | N87: =VALUE(TRIM(RIGHT(LEFT(SUBSTITUTE(G87,_xlfn.UNICHAR(8211),"-"),FIND("-",SUBSTITUTE(G87,_xlfn.UNICHAR(8211),"-"))-1),2))) -> 1 | O87: =VALUE(TRIM(LEFT(MID(SUBSTITUTE(G87,_xlfn.UNICHAR(8211),"-"),FIND("-",SUBSTITUTE(G87,_xlfn.UNICHAR(8211),"-"))+1,100),2))) -> 1 | P87: =IF(LEFT(TRIM(G87),1)="(",MID(TRIM(G87),2,FIND(")",TRIM(G87))-2)&"-"&MID(TRIM(G87),FIND("(",TRIM(G87),2)+1,LEN(TRIM(G87))-FIND("(",TRIM(G87),2)-1),"") -> 2-4
A88: Round of 32 | C88: Fri | D88: 46206 | E88: 18:00 (07:30) | F88: Argentina ar | G88: 3–2 | H88: cv Cabo Verde | I88: 64478 | J88: Hard Rock Stadium (Neutral Site) | K88: Drew Fischer | L88: Match Report | M88: Required Extra Time | N88: =VALUE(TRIM(RIGHT(LEFT(SUBSTITUTE(G88,_xlfn.UNICHAR(8211),"-"),FIND("-",SUBSTITUTE(G88,_xlfn.UNICHAR(8211),"-"))-1),2))) -> 3 | O88: =VALUE(TRIM(LEFT(MID(SUBSTITUTE(G88,_xlfn.UNICHAR(8211),"-"),FIND("-",SUBSTITUTE(G88,_xlfn.UNICHAR(8211),"-"))+1,100),2))) -> 2 | P88: =IF(LEFT(TRIM(G88),1)="(",MID(TRIM(G88),2,FIND(")",TRIM(G88))-2)&"-"&MID(TRIM(G88),FIND("(",TRIM(G88),2)+1,LEN(TRIM(G88))-FIND("(",TRIM(G88),2)-1),"")
A89: Round of 32 | C89: Fri | D89: 46206 | E89: 20:30 (11:00) | F89: Colombia co | G89: 1–0 | H89: gh Ghana | I89: 69045 | J89: GEHA Field at Arrowhead Stadium (Neutral Site) | K89: Clément Turpin | L89: Match Report | N89: =VALUE(TRIM(RIGHT(LEFT(SUBSTITUTE(G89,_xlfn.UNICHAR(8211),"-"),FIND("-",SUBSTITUTE(G89,_xlfn.UNICHAR(8211),"-"))-1),2))) -> 1 | O89: =VALUE(TRIM(LEFT(MID(SUBSTITUTE(G89,_xlfn.UNICHAR(8211),"-"),FIND("-",SUBSTITUTE(G89,_xlfn.UNICHAR(8211),"-"))+1,100),2))) -> 0 | P89: =IF(LEFT(TRIM(G89),1)="(",MID(TRIM(G89),2,FIND(")",TRIM(G89))-2)&"-"&MID(TRIM(G89),FIND("(",TRIM(G89),2)+1,LEN(TRIM(G89))-FIND("(",TRIM(G89),2)-1),"")
A90: Round of 16 | C90: Sat | D90: 46207 | E90: 12:00 (02:30) | F90: Canada ca | G90: 0–3 | H90: ma Morocco | I90: 68777 | J90: Reliant Stadium (Neutral Site) | K90: Michael Oliver | L90: Match Report | N90: =VALUE(TRIM(RIGHT(LEFT(SUBSTITUTE(G90,_xlfn.UNICHAR(8211),"-"),FIND("-",SUBSTITUTE(G90,_xlfn.UNICHAR(8211),"-"))-1),2))) -> 0 | O90: =VALUE(TRIM(LEFT(MID(SUBSTITUTE(G90,_xlfn.UNICHAR(8211),"-"),FIND("-",SUBSTITUTE(G90,_xlfn.UNICHAR(8211),"-"))+1,100),2))) -> 3 | P90: =IF(LEFT(TRIM(G90),1)="(",MID(TRIM(G90),2,FIND(")",TRIM(G90))-2)&"-"&MID(TRIM(G90),FIND("(",TRIM(G90),2)+1,LEN(TRIM(G90))-FIND("(",TRIM(G90),2)-1),"")
A91: Round of 16 | C91: Sat | D91: 46207 | E91: 17:00 (06:30) | F91: Paraguay py | G91: 0–1 | H91: fr France | I91: 68324 | J91: Lincoln Financial Field (Neutral Site) | K91: Ilgiz Tantashev | L91: Match Report | N91: =VALUE(TRIM(RIGHT(LEFT(SUBSTITUTE(G91,_xlfn.UNICHAR(8211),"-"),FIND("-",SUBSTITUTE(G91,_xlfn.UNICHAR(8211),"-"))-1),2))) -> 0 | O91: =VALUE(TRIM(LEFT(MID(SUBSTITUTE(G91,_xlfn.UNICHAR(8211),"-"),FIND("-",SUBSTITUTE(G91,_xlfn.UNICHAR(8211),"-"))+1,100),2))) -> 1 | P91: =IF(LEFT(TRIM(G91),1)="(",MID(TRIM(G91),2,FIND(")",TRIM(G91))-2)&"-"&MID(TRIM(G91),FIND("(",TRIM(G91),2)+1,LEN(TRIM(G91))-FIND("(",TRIM(G91),2)-1),"")
A92: Round of 16 | C92: Sun | D92: 46208 | E92: 16:00 (05:30) | F92: Brazil br | G92: 1–2 | H92: no Norway | I92: 80663 | J92: MetLife Stadium (Neutral Site) | K92: Ismail Elfath | L92: Match Report | N92: =VALUE(TRIM(RIGHT(LEFT(SUBSTITUTE(G92,_xlfn.UNICHAR(8211),"-"),FIND("-",SUBSTITUTE(G92,_xlfn.UNICHAR(8211),"-"))-1),2))) -> 1 | O92: =VALUE(TRIM(LEFT(MID(SUBSTITUTE(G92,_xlfn.UNICHAR(8211),"-"),FIND("-",SUBSTITUTE(G92,_xlfn.UNICHAR(8211),"-"))+1,100),2))) -> 2 | P92: =IF(LEFT(TRIM(G92),1)="(",MID(TRIM(G92),2,FIND(")",TRIM(G92))-2)&"-"&MID(TRIM(G92),FIND("(",TRIM(G92),2)+1,LEN(TRIM(G92))-FIND("(",TRIM(G92),2)-1),"")
A93: Round of 16 | C93: Sun | D93: 46208 | E93: 19:00 (10:30) | F93: Mexico mx | G93: 2–3 | H93: eng England | I93: 80824 | J93: Estadio Banorte (Neutral Site) | K93: Alireza Faghani | L93: Match Report | N93: =VALUE(TRIM(RIGHT(LEFT(SUBSTITUTE(G93,_xlfn.UNICHAR(8211),"-"),FIND("-",SUBSTITUTE(G93,_xlfn.UNICHAR(8211),"-"))-1),2))) -> 2 | O93: =VALUE(TRIM(LEFT(MID(SUBSTITUTE(G93,_xlfn.UNICHAR(8211),"-"),FIND("-",SUBSTITUTE(G93,_xlfn.UNICHAR(8211),"-"))+1,100),2))) -> 3 | P93: =IF(LEFT(TRIM(G93),1)="(",MID(TRIM(G93),2,FIND(")",TRIM(G93))-2)&"-"&MID(TRIM(G93),FIND("(",TRIM(G93),2)+1,LEN(TRIM(G93))-FIND("(",TRIM(G93),2)-1),"")
A94: Round of 16 | C94: Mon | D94: 46209 | E94: 14:00 (04:30) | F94: Portugal pt | G94: 0–1 | H94: es Spain | I94: 70649 | J94: AT&T Stadium (Neutral Site) | K94: Anthony Taylor | L94: Match Report | N94: =VALUE(TRIM(RIGHT(LEFT(SUBSTITUTE(G94,_xlfn.UNICHAR(8211),"-"),FIND("-",SUBSTITUTE(G94,_xlfn.UNICHAR(8211),"-"))-1),2))) -> 0 | O94: =VALUE(TRIM(LEFT(MID(SUBSTITUTE(G94,_xlfn.UNICHAR(8211),"-"),FIND("-",SUBSTITUTE(G94,_xlfn.UNICHAR(8211),"-"))+1,100),2))) -> 1 | P94: =IF(LEFT(TRIM(G94),1)="(",MID(TRIM(G94),2,FIND(")",TRIM(G94))-2)&"-"&MID(TRIM(G94),FIND("(",TRIM(G94),2)+1,LEN(TRIM(G94))-FIND("(",TRIM(G94),2)-1),"")
A95: Round of 16 | C95: Mon | D95: 46209 | E95: 17:00 (09:30) | F95: USA us | G95: 1–4 | H95: be Belgium | I95: 66925 | J95: Lumen Field (Neutral Site) | K95: Adham Makhadmeh | L95: Match Report | N95: =VALUE(TRIM(RIGHT(LEFT(SUBSTITUTE(G95,_xlfn.UNICHAR(8211),"-"),FIND("-",SUBSTITUTE(G95,_xlfn.UNICHAR(8211),"-"))-1),2))) -> 1 | O95: =VALUE(TRIM(LEFT(MID(SUBSTITUTE(G95,_xlfn.UNICHAR(8211),"-"),FIND("-",SUBSTITUTE(G95,_xlfn.UNICHAR(8211),"-"))+1,100),2))) -> 4 | P95: =IF(LEFT(TRIM(G95),1)="(",MID(TRIM(G95),2,FIND(")",TRIM(G95))-2)&"-"&MID(TRIM(G95),FIND("(",TRIM(G95),2)+1,LEN(TRIM(G95))-FIND("(",TRIM(G95),2)-1),"")
A96: Round of 16 | C96: Tue | D96: 46210 | E96: 12:00 (01:30) | F96: Argentina ar | G96: 3–2 | H96: eg Egypt | I96: 68239 | J96: Mercedes-Benz Stadium (Neutral Site) | K96: François Letexier | L96: Match Report | N96: =VALUE(TRIM(RIGHT(LEFT(SUBSTITUTE(G96,_xlfn.UNICHAR(8211),"-"),FIND("-",SUBSTITUTE(G96,_xlfn.UNICHAR(8211),"-"))-1),2))) -> 3 | O96: =VALUE(TRIM(LEFT(MID(SUBSTITUTE(G96,_xlfn.UNICHAR(8211),"-"),FIND("-",SUBSTITUTE(G96,_xlfn.UNICHAR(8211),"-"))+1,100),2))) -> 2 | P96: =IF(LEFT(TRIM(G96),1)="(",MID(TRIM(G96),2,FIND(")",TRIM(G96))-2)&"-"&MID(TRIM(G96),FIND("(",TRIM(G96),2)+1,LEN(TRIM(G96))-FIND("(",TRIM(G96),2)-1),"")
A97: Round of 16 | C97: Tue | D97: 46210 | E97: 13:00 (05:30) | F97: Switzerland ch | G97: (4) 0–0 (3) | H97: co Colombia | I97: 52497 | J97: BC Place Stadium (Neutral Site) | K97: Iván Barton | L97: Match Report | M97: Switzerland won a penalty shoot-out following extra time | N97: =VALUE(TRIM(RIGHT(LEFT(SUBSTITUTE(G97,_xlfn.UNICHAR(8211),"-"),FIND("-",SUBSTITUTE(G97,_xlfn.UNICHAR(8211),"-"))-1),2))) -> 0 | O97: =VALUE(TRIM(LEFT(MID(SUBSTITUTE(G97,_xlfn.UNICHAR(8211),"-"),FIND("-",SUBSTITUTE(G97,_xlfn.UNICHAR(8211),"-"))+1,100),2))) -> 0 | P97: =IF(LEFT(TRIM(G97),1)="(",MID(TRIM(G97),2,FIND(")",TRIM(G97))-2)&"-"&MID(TRIM(G97),FIND("(",TRIM(G97),2)+1,LEN(TRIM(G97))-FIND("(",TRIM(G97),2)-1),"") -> 4-3
A98: Quarter-finals | C98: Thu | D98: 46212 | E98: 16:00 (05:30) | F98: France fr | G98: 2–0 | H98: ma Morocco | I98: 63811 | J98: Gillette Stadium (Neutral Site) | K98: Facundo Tello | L98: Match Report | N98: =VALUE(TRIM(RIGHT(LEFT(SUBSTITUTE(G98,_xlfn.UNICHAR(8211),"-"),FIND("-",SUBSTITUTE(G98,_xlfn.UNICHAR(8211),"-"))-1),2))) -> 2 | O98: =VALUE(TRIM(LEFT(MID(SUBSTITUTE(G98,_xlfn.UNICHAR(8211),"-"),FIND("-",SUBSTITUTE(G98,_xlfn.UNICHAR(8211),"-"))+1,100),2))) -> 0 | P98: =IF(LEFT(TRIM(G98),1)="(",MID(TRIM(G98),2,FIND(")",TRIM(G98))-2)&"-"&MID(TRIM(G98),FIND("(",TRIM(G98),2)+1,LEN(TRIM(G98))-FIND("(",TRIM(G98),2)-1),"")
A99: Quarter-finals | C99: Fri | D99: 46213 | E99: 12:00 (04:30) | F99: Spain es | G99: 2–1 | H99: be Belgium | I99: 70492 | J99: SoFi Stadium (Neutral Site) | K99: Michael Oliver | L99: Match Report | N99: =VALUE(TRIM(RIGHT(LEFT(SUBSTITUTE(G99,_xlfn.UNICHAR(8211),"-"),FIND("-",SUBSTITUTE(G99,_xlfn.UNICHAR(8211),"-"))-1),2))) -> 2 | O99: =VALUE(TRIM(LEFT(MID(SUBSTITUTE(G99,_xlfn.UNICHAR(8211),"-"),FIND("-",SUBSTITUTE(G99,_xlfn.UNICHAR(8211),"-"))+1,100),2))) -> 1 | P99: =IF(LEFT(TRIM(G99),1)="(",MID(TRIM(G99),2,FIND(")",TRIM(G99))-2)&"-"&MID(TRIM(G99),FIND("(",TRIM(G99),2)+1,LEN(TRIM(G99))-FIND("(",TRIM(G99),2)-1),"")
...
